File: metingen/ruwe_csv/sample12mm-tension-G3b_1.csv
1,Time,Displacement,Force,Strain 1
,(s),(mm),(kN),(%)
"","0,0000","0,0000","0,2434","-0,0007"
"","0,1400","0,0004","0,2439","-0,0007"
"","0,2800","0,0023","0,2463","-0,0001"
"","0,4200","0,0062","0,2559","0,0022"
"","0,5600","0,0091","0,2621","0,0038"
"","0,7000","0,0114","0,2674","0,0050"
"","0,8400","0,0136","0,2714","0,0062"
"","0,9800","0,0160","0,2761","0,0075"
"","1,1200","0,0184","0,2815","0,0087"
"","1,2600","0,0206","0,2861","0,0098"
"","1,4000","0,0230","0,2897","0,0111"
"","1,5400","0,0253","0,2946","0,0123"
"","1,6800","0,0277","0,3001","0,0136"
"","1,8200","0,0300","0,3035","0,0147"
"","1,9600","0,0323","0,3088","0,0159"
"","2,1000","0,0347","0,3133","0,0171"
"","2,2400","0,0370","0,3180","0,0182"
"","2,3800","0,0393","0,3218","0,0193"
"","2,5200","0,0417","0,3263","0,0204"
"","2,6600","0,0440","0,3298","0,0216"
"","2,8000","0,0463","0,3362","0,0227"
"","2,9400","0,0487","0,3389","0,0239"
"","3,0800","0,0510","0,3436","0,0249"
"","3,2200","0,0533","0,3472","0,0260"
"","3,3600","0,0557","0,3511","0,0271"
"","3,5000","0,0580","0,3556","0,0281"
"","3,6400","0,0603","0,3590","0,0291"
"","3,7800","0,0627","0,3631","0,0302"
"","3,9200","0,0650","0,3671","0,0311"
"","4,0600","0,0673","0,3712","0,0322"
"","4,2000","0,0697","0,3741","0,0332"
"","4,3400","0,0720","0,3778","0,0340"
"","4,4800","0,0744","0,3823","0,0349"
"","4,6200","0,0767","0,3846","0,0358"
"","4,7600","0,0790","0,3883","0,0366"
"","4,9000","0,0814","0,3906","0,0374"
"","5,0400","0,0837","0,3934","0,0382"
"","5,1800","0,0859","0,3958","0,0389"
"","5,3200","0,0883","0,3986","0,0398"
"","5,4600","0,0907","0,4020","0,0405"
"","5,6000","0,0930","0,4045","0,0411"
"","5,7400","0,0954","0,4074","0,0419"
"","5,8800","0,0977","0,4100","0,0426"
"","6,0200","0,1000","0,4127","0,0433"
"","6,1600","0,1024","0,4140","0,0440"
"","6,3000","0,1047","0,4175","0,0447"
"","6,4400","0,1070","0,4199","0,0453"
"","6,5800","0,1094","0,4221","0,0460"
"","6,7200","0,1116","0,4249","0,0467"
"","6,8600","0,1140","0,4283","0,0474"
"","7,0000","0,1164","0,4304","0,0481"
"","7,1400","0,1187","0,4320","0,0487"
"","7,2800","0,1210","0,4361","0,0494"
"","7,4200","0,1233","0,4369","0,0501"
"","7,5600","0,1256","0,4405","0,0508"
"","7,7000","0,1280","0,4433","0,0515"
"","7,8400","0,1303","0,4446","0,0522"
"","7,9800","0,1326","0,4483","0,0528"
"","8,1200","0,1351","0,4504","0,0535"
"","8,2600","0,1374","0,4531","0,0542"
"","8,4000","0,1396","0,4558","0,0549"
"","8,5400","0,1421","0,4587","0,0556"
"","8,6800","0,1443","0,4603","0,0563"
"","8,8200","0,1466","0,4633","0,0570"
"","8,9600","0,1490","0,4654","0,0577"
"","9,1000","0,1513","0,4681","0,0584"
"","9,2400","0,1537","0,4710","0,0591"
"","9,3800","0,1560","0,4743","0,0597"
"","9,5200","0,1583","0,4755","0,0604"
"","9,6600","0,1607","0,4782","0,0611"
"","9,8000","0,1630","0,4813","0,0619"
"","9,9400","0,1653","0,4834","0,0625"
"","10,0800","0,1677","0,4857","0,0632"
"","10,2200","0,1700","0,4887","0,0639"
"","10,3600","0,1722","0,4909","0,0646"
"","10,5000","0,1747","0,4936","0,0653"
"","10,6400","0,1770","0,4958","0,0661"
"","10,7800","0,1793","0,4991","0,0667"
"","10,9200","0,1817","0,5015","0,0674"
"","11,0600","0,1840","0,5040","0,0681"
"","11,2000","0,1863","0,5072","0,0689"
"","11,3400","0,1887","0,5107","0,0696"
"","11,4800","0,1910","0,5115","0,0702"
"","11,6200","0,1933","0,5144","0,0709"
"","11,7600","0,1957","0,5174","0,0717"
"","11,9000","0,1980","0,5198","0,0724"
"","12,0400","0,2003","0,5226","0,0731"
"","12,1800","0,2027","0,5243","0,0738"
"","12,3200","0,2050","0,5278","0,0744"
"","12,4600","0,2074","0,5294","0,0752"
"","12,6000","0,2097","0,5321","0,0758"
"","12,7400","0,2120","0,5354","0,0766"
"","12,8800","0,2144","0,5379","0,0773"
"","13,0200","0,2167","0,5402","0,0780"
"","13,1600","0,2189","0,5424","0,0786"
"","13,3000","0,2214","0,5458","0,0794"
"","13,4400","0,2237","0,5476","0,0801"
"","13,5800","0,2260","0,5505","0,0808"
"","13,7200","0,2284","0,5537","0,0816"
"","13,8600","0,2307","0,5561","0,0823"
"","14,0000","0,2330","0,5582","0,0829"
"","14,1400","0,2354","0,5615","0,0837"
"","14,2800","0,2376","0,5633","0,0844"
"","14,4200","0,2400","0,5661","0,0851"
"","14,5600","0,2423","0,5674","0,0858"
"","14,7000","0,2446","0,5701","0,0864"
"","14,8400","0,2470","0,5737","0,0873"
"","14,9800","0,2494","0,5759","0,0879"
"","15,1200","0,2517","0,5777","0,0886"
"","15,2600","0,2541","0,5816","0,0893"
"","15,4000","0,2563","0,5837","0,0900"
"","15,5400","0,2586","0,5858","0,0906"
"","15,6800","0,2610","0,5879","0,0913"
"","15,8200","0,2633","0,5906","0,0920"
"","15,9600","0,2656","0,5923","0,0926"
"","16,1000","0,2680","0,5954","0,0933"
"","16,2400","0,2704","0,5991","0,0940"
"","16,3800","0,2726","0,6013","0,0946"
"","16,5200","0,2750","0,6029","0,0953"
"","16,6600","0,2774","0,6051","0,0959"
"","16,8000","0,2797","0,6079","0,0966"
"","16,9400","0,2820","0,6109","0,0973"
"","17,0800","0,2844","0,6134","0,0980"
"","17,2200","0,2867","0,6145","0,0986"
"","17,3600","0,2890","0,6165","0,0992"
"","17,5000","0,2912","0,6188","0,0999"
"","17,6400","0,2937","0,6234","0,1006"
"","17,7800","0,2960","0,6243","0,1013"
"","17,9200","0,2983","0,6269","0,1019"
"","18,0600","0,3007","0,6298","0,1026"
"","18,2000","0,3030","0,6308","0,1032"
"","18,3400","0,3053","0,6334","0,1039"
"","18,4800","0,3077","0,6370","0,1046"
"","18,6200","0,3100","0,6389","0,1051"
"","18,7600","0,3122","0,6403","0,1057"
"","18,9000","0,3147","0,6413","0,1064"
"","19,0400","0,3170","0,6450","0,1070"
"","19,1800","0,3193","0,6463","0,1075"
"","19,3200","0,3217","0,6493","0,1082"
"","19,4600","0,3240","0,6523","0,1087"
"","19,6000","0,3263","0,6532","0,1093"
"","19,7400","0,3287","0,6558","0,1100"
"","19,8800","0,3310","0,6568","0,1106"
"","20,0200","0,3334","0,6607","0,1112"
"","20,1600","0,3357","0,6620","0,1118"
"","20,3000","0,3379","0,6646","0,1123"
"","20,4400","0,3404","0,6666","0,1130"
"","20,5800","0,3427","0,6684","0,1135"
"","20,7200","0,3449","0,6701","0,1140"
"","20,8600","0,3474","0,6725","0,1147"
"","21,0000","0,3497","0,6752","0,1153"
"","21,1400","0,3519","0,6766","0,1159"
"","21,2800","0,3543","0,6787","0,1166"
"","21,4200","0,3566","0,6802","0,1172"
"","21,5600","0,3589","0,6839","0,1178"
"","21,7000","0,3614","0,6856","0,1184"
"","21,8400","0,3637","0,6881","0,1191"
"","21,9800","0,3660","0,6909","0,1197"
"","22,1200","0,3684","0,6927","0,1204"
"","22,2600","0,3706","0,6943","0,1209"
"","22,4000","0,3730","0,6967","0,1216"
"","22,5400","0,3754","0,6995","0,1223"
"","22,6800","0,3777","0,7020","0,1229"
"","22,8200","0,3800","0,7037","0,1236"
"","22,9600","0,3824","0,7066","0,1242"
"","23,1000","0,3846","0,7077","0,1248"
"","23,2400","0,3871","0,7112","0,1255"
"","23,3800","0,3893","0,7122","0,1262"
"","23,5200","0,3916","0,7158","0,1268"
"","23,6600","0,3940","0,7178","0,1275"
"","23,8000","0,3964","0,7193","0,1281"
"","23,9400","0,3986","0,7234","0,1288"
"","24,0800","0,4010","0,7254","0,1295"
"","24,2200","0,4033","0,7272","0,1302"
"","24,3600","0,4056","0,7298","0,1308"
"","24,5000","0,4080","0,7321","0,1316"
"","24,6400","0,4104","0,7343","0,1322"
"","24,7800","0,4127","0,7372","0,1329"
"","24,9200","0,4150","0,7396","0,1335"
"","25,0600","0,4173","0,7424","0,1342"
"","25,2000","0,4197","0,7445","0,1349"
"","25,3400","0,4220","0,7461","0,1356"
"","25,4800","0,4242","0,7495","0,1362"
"","25,6200","0,4267","0,7519","0,1370"
"","25,7600","0,4290","0,7546","0,1376"
"","25,9000","0,4313","0,7559","0,1383"
"","26,0400","0,4337","0,7597","0,1390"
"","26,1800","0,4360","0,7621","0,1397"
"","26,3200","0,4383","0,7636","0,1403"
"","26,4600","0,4407","0,7666","0,1411"
"","26,6000","0,4430","0,7683","0,1417"
"","26,7400","0,4453","0,7714","0,1423"
"","26,8800","0,4477","0,7747","0,1431"
"","27,0200","0,4500","0,7755","0,1437"
"","27,1600","0,4523","0,7771","0,1444"
"","27,3000","0,4547","0,7805","0,1451"
"","27,4400","0,4570","0,7835","0,1458"
"","27,5800","0,4594","0,7851","0,1465"
"","27,7200","0,4617","0,7878","0,1472"
"","27,8600","0,4640","0,7892","0,1478"
"","28,0000","0,4664","0,7927","0,1486"
"","28,1400","0,4686","0,7952","0,1492"
"","28,2800","0,4709","0,7973","0,1498"
"","28,4200","0,4734","0,7991","0,1506"
"","28,5600","0,4757","0,8027","0,1513"
"","28,7000","0,4780","0,8045","0,1519"
"","28,8400","0,4804","0,8067","0,1527"
"","28,9800","0,4827","0,8082","0,1533"
"","29,1200","0,4850","0,8115","0,1540"
"","29,2600","0,4874","0,8144","0,1548"
"","29,4000","0,4897","0,8157","0,1554"
"","29,5400","0,4919","0,8192","0,1560"
"","29,6800","0,4944","0,8211","0,1568"
"","29,8200","0,4967","0,8241","0,1575"
"","29,9600","0,4990","0,8265","0,1582"
"","30,1000","0,5014","0,8271","0,1589"
"","30,2400","0,5037","0,8312","0,1596"
"","30,3800","0,5060","0,8332","0,1602"
"","30,5200","0,5084","0,8346","0,1609"
"","30,6600","0,5107","0,8380","0,1616"
"","30,8000","0,5130","0,8400","0,1623"
"","30,9400","0,5153","0,8416","0,1630"
"","31,0800","0,5176","0,8447","0,1636"
"","31,2200","0,5201","0,8469","0,1644"
"","31,3600","0,5223","0,8500","0,1651"
"","31,5000","0,5246","0,8519","0,1657"
"","31,6400","0,5270","0,8547","0,1664"
"","31,7800","0,5293","0,8562","0,1671"
"","31,9200","0,5316","0,8581","0,1677"
"","32,0600","0,5340","0,8611","0,1685"
"","32,2000","0,5363","0,8646","0,1692"
"","32,3400","0,5386","0,8662","0,1698"
"","32,4800","0,5410","0,8687","0,1705"
"","32,6200","0,5433","0,8704","0,1712"
"","32,7600","0,5457","0,8744","0,1720"
"","32,9000","0,5480","0,8763","0,1726"
"","33,0400","0,5503","0,8784","0,1732"
"","33,1800","0,5527","0,8809","0,1740"
"","33,3200","0,5550","0,8826","0,1747"
"","33,4600","0,5573","0,8862","0,1754"
"","33,6000","0,5597","0,8874","0,1761"
"","33,7400","0,5620","0,8905","0,1768"
"","33,8800","0,5643","0,8919","0,1774"
"","34,0200","0,5667","0,8945","0,1782"
"","34,1600","0,5690","0,8975","0,1788"
"","34,3000","0,5713","0,8989","0,1795"
"","34,4400","0,5737","0,9020","0,1802"
"","34,5800","0,5760","0,9041","0,1809"
"","34,7200","0,5783","0,9055","0,1816"
"","34,8600","0,5807","0,9095","0,1823"
"","35,0000","0,5830","0,9110","0,1830"
"","35,1400","0,5853","0,9140","0,1837"
"","35,2800","0,5877","0,9165","0,1845"
"","35,4200","0,5900","0,9186","0,1851"
"","35,5600","0,5924","0,9205","0,1858"
"","35,7000","0,5947","0,9236","0,1865"
"","35,8400","0,5969","0,9251","0,1872"
"","35,9800","0,5994","0,9280","0,1879"
"","36,1200","0,6017","0,9303","0,1886"
"","36,2600","0,6039","0,9322","0,1893"
"","36,4000","0,6064","0,9354","0,1900"
"","36,5400","0,6087","0,9380","0,1907"
"","36,6800","0,6110","0,9401","0,1914"
"","36,8200","0,6134","0,9420","0,1922"
"","36,9600","0,6157","0,9450","0,1929"
"","37,1000","0,6180","0,9473","0,1935"
"","37,2400","0,6204","0,9495","0,1942"
"","37,3800","0,6226","0,9511","0,1949"
"","37,5200","0,6249","0,9540","0,1956"
"","37,6600","0,6273","0,9574","0,1964"
"","37,8000","0,6296","0,9591","0,1970"
"","37,9400","0,6320","0,9605","0,1978"
"","38,0800","0,6344","0,9632","0,1985"
"","38,2200","0,6367","0,9656","0,1992"
"","38,3600","0,6390","0,9692","0,1999"
"","38,5000","0,6414","0,9724","0,2006"
"","38,6400","0,6436","0,9729","0,2013"
"","38,7800","0,6460","0,9758","0,2021"
"","38,9200","0,6483","0,9775","0,2027"
"","39,0600","0,6506","0,9814","0,2034"
"","39,2000","0,6530","0,9829","0,2042"
"","39,3400","0,6554","0,9856","0,2049"
"","39,4800","0,6577","0,9873","0,2055"
"","39,6200","0,6601","0,9903","0,2063"
"","39,7600","0,6623","0,9926","0,2070"
"","39,9000","0,6647","0,9942","0,2077"
"","40,0400","0,6670","0,9977","0,2084"
"","40,1800","0,6693","0,9986","0,2091"
"","40,3200","0,6716","1,0015","0,2098"
"","40,4600","0,6740","1,0059","0,2105"
"","40,6000","0,6763","1,0062","0,2112"
"","40,7400","0,6787","1,0096","0,2120"
"","40,8800","0,6811","1,0113","0,2128"
"","41,0200","0,6833","1,0138","0,2134"
"","41,1600","0,6857","1,0154","0,2141"
"","41,3000","0,6881","1,0163","0,2148"
"","41,4400","0,6903","1,0204","0,2156"
"","41,5800","0,6927","1,0242","0,2163"
"","41,7200","0,6950","1,0256","0,2170"
"","41,8600","0,6972","1,0270","0,2177"
"","42,0000","0,6997","1,0307","0,2185"
"","42,1400","0,7020","1,0342","0,2192"
"","42,2800","0,7043","1,0351","0,2199"
"","42,4200","0,7067","1,0373","0,2206"
"","42,5600","0,7090","1,0397","0,2213"
"","42,7000","0,7113","1,0417","0,2220"
"","42,8400","0,7137","1,0430","0,2227"
"","42,9800","0,7159","1,0466","0,2234"
"","43,1200","0,7183","1,0488","0,2240"
"","43,2600","0,7206","1,0510","0,2248"
"","43,4000","0,7229","1,0538","0,2255"
"","43,5400","0,7254","1,0562","0,2263"
"","43,6800","0,7277","1,0578","0,2270"
"","43,8200","0,7300","1,0609","0,2277"
"","43,9600","0,7324","1,0631","0,2284"
"","44,1000","0,7347","1,0653","0,2291"
"","44,2400","0,7370","1,0678","0,2298"
"","44,3800","0,7394","1,0706","0,2305"
"","44,5200","0,7417","1,0718","0,2312"
"","44,6600","0,7439","1,0748","0,2320"
"","44,8000","0,7464","1,0775","0,2327"
"","44,9400","0,7486","1,0788","0,2334"
"","45,0800","0,7509","1,0822","0,2342"
"","45,2200","0,7534","1,0848","0,2349"
"","45,3600","0,7557","1,0875","0,2356"
"","45,5000","0,7580","1,0896","0,2363"
"","45,6400","0,7604","1,0919","0,2371"
"","45,7800","0,7627","1,0943","0,2378"
"","45,9200","0,7650","1,0955","0,2385"
"","46,0600","0,7673","1,0988","0,2392"
"","46,2000","0,7696","1,1017","0,2399"
"","46,3400","0,7720","1,1037","0,2407"
"","46,4800","0,7743","1,1061","0,2415"
"","46,6200","0,7766","1,1080","0,2421"
"","46,7600","0,7791","1,1110","0,2430"
"","46,9000","0,7814","1,1129","0,2437"
"","47,0400","0,7836","1,1153","0,2444"
"","47,1800","0,7860","1,1183","0,2451"
"","47,3200","0,7883","1,1199","0,2458"
"","47,4600","0,7906","1,1222","0,2465"
"","47,6000","0,7930","1,1227","0,2472"
"","47,7400","0,7953","1,1267","0,2479"
"","47,8800","0,7976","1,1294","0,2487"
"","48,0200","0,8000","1,1317","0,2495"
"","48,1600","0,8023","1,1343","0,2502"
"","48,3000","0,8047","1,1368","0,2509"
"","48,4400","0,8071","1,1391","0,2517"
"","48,5800","0,8093","1,1394","0,2523"
"","48,7200","0,8117","1,1445","0,2531"
"","48,8600","0,8140","1,1457","0,2538"
"","49,0000","0,8163","1,1471","0,2545"
"","49,1400","0,8186","1,1498","0,2553"
"","49,2800","0,8209","1,1536","0,2560"
"","49,4200","0,8233","1,1550","0,2567"
"","49,5600","0,8257","1,1577","0,2576"
"","49,7000","0,8280","1,1590","0,2582"
"","49,8400","0,8303","1,1623","0,2589"
"","49,9800","0,8327","1,1646","0,2598"
"","50,1200","0,8350","1,1663","0,2604"
"","50,2600","0,8373","1,1692","0,2611"
"","50,4000","0,8397","1,1711","0,2619"
"","50,5400","0,8419","1,1734","0,2626"
"","50,6800","0,8443","1,1766","0,2634"
"","50,8200","0,8467","1,1783","0,2641"
"","50,9600","0,8490","1,1803","0,2648"
"","51,1000","0,8514","1,1835","0,2656"
"","51,2400","0,8537","1,1843","0,2664"
"","51,3800","0,8560","1,1880","0,2672"
"","51,5200","0,8584","1,1910","0,2679"
"","51,6600","0,8607","1,1926","0,2686"
"","51,8000","0,8629","1,1949","0,2693"
"","51,9400","0,8653","1,1958","0,2701"
"","52,0800","0,8677","1,1998","0,2708"
"","52,2200","0,8699","1,2025","0,2715"
"","52,3600","0,8724","1,2042","0,2724"
"","52,5000","0,8747","1,2060","0,2731"
"","52,6400","0,8770","1,2086","0,2738"
"","52,7800","0,8794","1,2115","0,2746"
"","52,9200","0,8817","1,2150","0,2753"
"","53,0600","0,8839","1,2162","0,2760"
"","53,2000","0,8863","1,2180","0,2768"
"","53,3400","0,8886","1,2206","0,2776"
"","53,4800","0,8910","1,2221","0,2783"
"","53,6200","0,8933","1,2252","0,2791"
"","53,7600","0,8956","1,2286","0,2798"
"","53,9000","0,8980","1,2303","0,2806"
"","54,0400","0,9004","1,2318","0,2813"
"","54,1800","0,9027","1,2345","0,2821"
"","54,3200","0,9051","1,2370","0,2830"
"","54,4600","0,9073","1,2390","0,2836"
"","54,6000","0,9096","1,2405","0,2843"
"","54,7400","0,9120","1,2449","0,2851"
"","54,8800","0,9144","1,2462","0,2859"
"","55,0200","0,9166","1,2479","0,2866"
"","55,1600","0,9190","1,2498","0,2873"
"","55,3000","0,9214","1,2530","0,2881"
"","55,4400","0,9237","1,2550","0,2888"
"","55,5800","0,9261","1,2580","0,2897"
"","55,7200","0,9283","1,2600","0,2904"
"","55,8600","0,9306","1,2622","0,2911"
"","56,0000","0,9330","1,2635","0,2918"
"","56,1400","0,9353","1,2658","0,2926"
"","56,2800","0,9376","1,2693","0,2934"
"","56,4200","0,9400","1,2708","0,2941"
"","56,5600","0,9423","1,2733","0,2948"
"","56,7000","0,9447","1,2753","0,2956"
"","56,8400","0,9470","1,2787","0,2964"
"","56,9800","0,9493","1,2806","0,2971"
"","57,1200","0,9517","1,2831","0,2979"
"","57,2600","0,9540","1,2855","0,2987"
"","57,4000","0,9563","1,2870","0,2994"
"","57,5400","0,9587","1,2895","0,3002"
"","57,6800","0,9610","1,2916","0,3009"
"","57,8200","0,9632","1,2943","0,3017"
"","57,9600","0,9657","1,2965","0,3025"
"","58,1000","0,9680","1,2993","0,3032"
"","58,2400","0,9703","1,3011","0,3040"
"","58,3800","0,9727","1,3031","0,3047"
"","58,5200","0,9750","1,3058","0,3054"
"","58,6600","0,9773","1,3089","0,3062"
"","58,8000","0,9797","1,3101","0,3070"
"","58,9400","0,9820","1,3124","0,3077"
"","59,0800","0,9843","1,3161","0,3085"
"","59,2200","0,9867","1,3168","0,3092"
"","59,3600","0,9890","1,3194","0,3100"
"","59,5000","0,9914","1,3215","0,3108"
"","59,6400","0,9937","1,3251","0,3115"
"","59,7800","0,9960","1,3260","0,3123"
"","59,9200","0,9984","1,3280","0,3131"
"","60,0600","1,0007","1,3298","0,3139"
"","60,2000","1,0030","1,3326","0,3146"
"","60,3400","1,0054","1,3363","0,3155"
"","60,4800","1,0076","1,3370","0,3162"
"","60,6200","1,0099","1,3397","0,3169"
"","60,7600","1,0124","1,3412","0,3178"
"","60,9000","1,0147","1,3454","0,3185"
"","61,0400","1,0170","1,3463","0,3192"
"","61,1800","1,0194","1,3492","0,3201"
"","61,3200","1,0217","1,3511","0,3208"
"","61,4600","1,0240","1,3528","0,3216"
"","61,6000","1,0263","1,3555","0,3224"
"","61,7400","1,0286","1,3580","0,3231"
"","61,8800","1,0310","1,3615","0,3239"
"","62,0200","1,0334","1,3624","0,3247"
"","62,1600","1,0356","1,3649","0,3255"
"","62,3000","1,0380","1,3672","0,3263"
"","62,4400","1,0404","1,3694","0,3271"
"","62,5800","1,0426","1,3715","0,3279"
"","62,7200","1,0450","1,3743","0,3286"
"","62,8600","1,0474","1,3758","0,3295"
"","63,0000","1,0496","1,3778","0,3302"
"","63,1400","1,0520","1,3809","0,3311"
"","63,2800","1,0544","1,3825","0,3319"
"","63,4200","1,0566","1,3855","0,3327"
"","63,5600","1,0591","1,3884","0,3335"
"","63,7000","1,0613","1,3901","0,3342"
"","63,8400","1,0636","1,3916","0,3350"
"","63,9800","1,0660","1,3949","0,3358"
"","64,1200","1,0683","1,3974","0,3366"
"","64,2600","1,0707","1,3985","0,3373"
"","64,4000","1,0730","1,4011","0,3381"
"","64,5400","1,0752","1,4037","0,3388"
"","64,6800","1,0777","1,4053","0,3397"
"","64,8200","1,0800","1,4079","0,3405"
"","64,9600","1,0823","1,4093","0,3413"
"","65,1000","1,0847","1,4122","0,3421"
"","65,2400","1,0870","1,4138","0,3429"
"","65,3800","1,0893","1,4178","0,3436"
"","65,5200","1,0917","1,4200","0,3445"
"","65,6600","1,0940","1,4219","0,3453"
"","65,8000","1,0963","1,4239","0,3460"
"","65,9400","1,0987","1,4256","0,3469"
"","66,0800","1,1010","1,4280","0,3476"
"","66,2200","1,1033","1,4302","0,3484"
"","66,3600","1,1057","1,4315","0,3493"
"","66,5000","1,1080","1,4354","0,3500"
"","66,6400","1,1103","1,4375","0,3508"
"","66,7800","1,1127","1,4385","0,3516"
"","66,9200","1,1150","1,4420","0,3524"
"","67,0600","1,1173","1,4444","0,3532"
"","67,2000","1,1197","1,4463","0,3540"
"","67,3400","1,1220","1,4479","0,3548"
"","67,4800","1,1243","1,4499","0,3556"
"","67,6200","1,1266","1,4527","0,3564"
"","67,7600","1,1289","1,4557","0,3572"
"","67,9000","1,1314","1,4574","0,3580"
"","68,0400","1,1337","1,4588","0,3588"
"","68,1800","1,1359","1,4610","0,3596"
"","68,3200","1,1384","1,4646","0,3604"
"","68,4600","1,1407","1,4660","0,3612"
"","68,6000","1,1429","1,4678","0,3620"
"","68,7400","1,1454","1,4700","0,3629"
"","68,8800","1,1477","1,4717","0,3636"
"","69,0200","1,1500","1,4746","0,3643"
"","69,1600","1,1523","1,4777","0,3651"
"","69,3000","1,1546","1,4791","0,3659"
"","69,4400","1,1570","1,4818","0,3667"
"","69,5800","1,1594","1,4828","0,3675"
"","69,7200","1,1616","1,4850","0,3683"
"","69,8600","1,1640","1,4881","0,3691"
"","70,0000","1,1664","1,4902","0,3700"
"","70,1400","1,1686","1,4921","0,3708"
"","70,2800","1,1710","1,4946","0,3716"
"","70,4200","1,1733","1,4971","0,3724"
"","70,5600","1,1756","1,4983","0,3731"
"","70,7000","1,1780","1,5003","0,3740"
"","70,8400","1,1803","1,5033","0,3748"
"","70,9800","1,1826","1,5050","0,3756"
"","71,1200","1,1850","1,5067","0,3764"
"","71,2600","1,1873","1,5093","0,3772"
"","71,4000","1,1896","1,5124","0,3780"
"","71,5400","1,1920","1,5136","0,3788"
"","71,6800","1,1943","1,5156","0,3796"
"","71,8200","1,1966","1,5186","0,3804"
"","71,9600","1,1990","1,5211","0,3812"
"","72,1000","1,2013","1,5216","0,3820"
"","72,2400","1,2037","1,5243","0,3829"
"","72,3800","1,2060","1,5269","0,3837"
"","72,5200","1,2083","1,5284","0,3845"
"","72,6600","1,2107","1,5317","0,3853"
"","72,8000","1,2130","1,5336","0,3862"
"","72,9400","1,2153","1,5354","0,3870"
"","73,0800","1,2177","1,5388","0,3878"
"","73,2200","1,2200","1,5400","0,3886"
"","73,3600","1,2222","1,5412","0,3894"
"","73,5000","1,2247","1,5448","0,3903"
"","73,6400","1,2270","1,5453","0,3911"
"","73,7800","1,2293","1,5484","0,3919"
"","73,9200","1,2317","1,5506","0,3927"
"","74,0600","1,2340","1,5536","0,3935"
"","74,2000","1,2363","1,5545","0,3943"
"","74,3400","1,2387","1,5570","0,3951"
"","74,4800","1,2410","1,5600","0,3960"
"","74,6200","1,2433","1,5607","0,3968"
"","74,7600","1,2456","1,5627","0,3976"
"","74,9000","1,2479","1,5657","0,3984"
"","75,0400","1,2503","1,5675","0,3992"
"","75,1800","1,2526","1,5690","0,4001"
"","75,3200","1,2549","1,5719","0,4008"
"","75,4600","1,2574","1,5739","0,4017"
"","75,6000","1,2597","1,5764","0,4025"
"","75,7400","1,2620","1,5772","0,4033"
"","75,8800","1,2644","1,5806","0,4042"
"","76,0200","1,2666","1,5822","0,4050"
"","76,1600","1,2689","1,5823","0,4058"
"","76,3000","1,2713","1,5871","0,4066"
"","76,4400","1,2737","1,5877","0,4074"
"","76,5800","1,2759","1,5919","0,4083"
"","76,7200","1,2784","1,5925","0,4091"
"","76,8600","1,2807","1,5941","0,4099"
"","77,0000","1,2831","1,5971","0,4108"
"","77,1400","1,2854","1,5986","0,4116"
"","77,2800","1,2876","1,6011","0,4124"
"","77,4200","1,2900","1,6031","0,4132"
"","77,5600","1,2923","1,6058","0,4141"
"","77,7000","1,2946","1,6070","0,4149"
"","77,8400","1,2970","1,6093","0,4157"
"","77,9800","1,2993","1,6115","0,4166"
"","78,1200","1,3016","1,6147","0,4174"
"","78,2600","1,3040","1,6154","0,4182"
"","78,4000","1,3064","1,6169","0,4191"
"","78,5400","1,3087","1,6209","0,4199"
"","78,6800","1,3111","1,6220","0,4207"
"","78,8200","1,3133","1,6246","0,4216"
"","78,9600","1,3156","1,6256","0,4224"
"","79,1000","1,3180","1,6275","0,4232"
"","79,2400","1,3203","1,6296","0,4240"
"","79,3800","1,3226","1,6319","0,4249"
"","79,5200","1,3250","1,6328","0,4258"
"","79,6600","1,3274","1,6363","0,4266"
"","79,8000","1,3298","1,6381","0,4274"
"","79,9400","1,3320","1,6407","0,4282"
"","80,0800","1,3343","1,6418","0,4291"
"","80,2200","1,3367","1,6433","0,4299"
"","80,3600","1,3390","1,6462","0,4307"
"","80,5000","1,3412","1,6478","0,4315"
"","80,6400","1,3436","1,6494","0,4323"
"","80,7800","1,3460","1,6520","0,4332"
"","80,9200","1,3482","1,6536","0,4340"
"","81,0600","1,3507","1,6564","0,4348"
"","81,2000","1,3531","1,6584","0,4357"
"","81,3400","1,3553","1,6601","0,4365"
"","81,4800","1,3577","1,6617","0,4374"
"","81,6200","1,3600","1,6635","0,4382"
"","81,7600","1,3623","1,6659","0,4390"
"","81,9000","1,3647","1,6676","0,4398"
"","82,0400","1,3669","1,6703","0,4407"
"","82,1800","1,3693","1,6721","0,4416"
"","82,3200","1,3717","1,6746","0,4425"
"","82,4600","1,3740","1,6757","0,4433"
"","82,6000","1,3764","1,6778","0,4441"
"","82,7400","1,3787","1,6810","0,4450"
"","82,8800","1,3810","1,6820","0,4458"
"","83,0200","1,3834","1,6844","0,4467"
"","83,1600","1,3856","1,6863","0,4475"
"","83,3000","1,3879","1,6873","0,4483"
"","83,4400","1,3904","1,6909","0,4493"
"","83,5800","1,3927","1,6920","0,4501"
"","83,7200","1,3949","1,6937","0,4509"
"","83,8600","1,3974","1,6970","0,4518"
"","84,0000","1,3997","1,6979","0,4527"
"","84,1400","1,4020","1,6999","0,4534"
"","84,2800","1,4044","1,7014","0,4543"
"","84,4200","1,4067","1,7043","0,4553"
"","84,5600","1,4090","1,7052","0,4561"
"","84,7000","1,4113","1,7067","0,4569"
"","84,8400","1,4136","1,7099","0,4577"
"","84,9800","1,4159","1,7122","0,4586"
"","85,1200","1,4184","1,7139","0,4596"
"","85,2600","1,4206","1,7155","0,4604"
"","85,4000","1,4230","1,7186","0,4613"
"","85,5400","1,4253","1,7191","0,4621"
"","85,6800","1,4276","1,7215","0,4630"
"","85,8200","1,4300","1,7246","0,4639"
"","85,9600","1,4323","1,7261","0,4647"
"","86,1000","1,4346","1,7277","0,4655"
"","86,2400","1,4370","1,7294","0,4664"
"","86,3800","1,4393","1,7320","0,4673"
"","86,5200","1,4416","1,7337","0,4681"
"","86,6600","1,4440","1,7353","0,4691"
"","86,8000","1,4464","1,7376","0,4699"
"","86,9400","1,4487","1,7393","0,4708"
"","87,0800","1,4511","1,7422","0,4717"
"","87,2200","1,4534","1,7440","0,4725"
"","87,3600","1,4557","1,7461","0,4734"
"","87,5000","1,4580","1,7467","0,4743"
"","87,6400","1,4603","1,7489","0,4751"
"","87,7800","1,4627","1,7514","0,4760"
"","87,9200","1,4650","1,7530","0,4769"
"","88,0600","1,4673","1,7547","0,4777"
"","88,2000","1,4697","1,7579","0,4786"
"","88,3400","1,4720","1,7583","0,4795"
"","88,4800","1,4743","1,7600","0,4803"
"","88,6200","1,4767","1,7621","0,4813"
"","88,7600","1,4790","1,7640","0,4821"
"","88,9000","1,4813","1,7675","0,4830"
"","89,0400","1,4837","1,7680","0,4838"
"","89,1800","1,4860","1,7699","0,4847"
"","89,3200","1,4883","1,7712","0,4855"
"","89,4600","1,4907","1,7735","0,4865"
"","89,6000","1,4930","1,7755","0,4873"
"","89,7400","1,4953","1,7783","0,4882"
"","89,8800","1,4977","1,7791","0,4891"
"","90,0200","1,5000","1,7810","0,4900"
"","90,1600","1,5023","1,7833","0,4909"
"","90,3000","1,5047","1,7853","0,4917"
"","90,4400","1,5070","1,7866","0,4925"
"","90,5800","1,5094","1,7878","0,4934"
"","90,7200","1,5117","1,7905","0,4943"
"","90,8600","1,5140","1,7925","0,4951"
"","91,0000","1,5164","1,7947","0,4961"
"","91,1400","1,5187","1,7964","0,4970"
"","91,2800","1,5209","1,7973","0,4978"
"","91,4200","1,5233","1,7996","0,4986"
"","91,5600","1,5257","1,8019","0,4996"
"","91,7000","1,5280","1,8030","0,5004"
"","91,8400","1,5304","1,8055","0,5013"
"","91,9800","1,5327","1,8057","0,5022"
"","92,1200","1,5350","1,8091","0,5030"
"","92,2600","1,5374","1,8108","0,5040"
"","92,4000","1,5397","1,8127","0,5048"
"","92,5400","1,5420","1,8145","0,5057"
"","92,6800","1,5443","1,8165","0,5066"
"","92,8200","1,5466","1,8178","0,5074"
"","92,9600","1,5490","1,8202","0,5084"
"","93,1000","1,5514","1,8218","0,5094"
"","93,2400","1,5536","1,8231","0,5101"
"","93,3800","1,5560","1,8253","0,5110"
"","93,5200","1,5583","1,8261","0,5119"
"","93,6600","1,5606","1,8296","0,5128"
"","93,8000","1,5630","1,8322","0,5137"
"","93,9400","1,5653","1,8334","0,5146"
"","94,0800","1,5676","1,8342","0,5155"
"","94,2200","1,5700","1,8361","0,5164"
"","94,3600","1,5724","1,8378","0,5172"
"","94,5000","1,5746","1,8397","0,5181"
"","94,6400","1,5771","1,8404","0,5190"
"","94,7800","1,5794","1,8430","0,5199"
"","94,9200","1,5816","1,8447","0,5185"
"","95,0600","1,5840","1,8459","0,5195"
"","95,2000","1,5864","1,8479","0,5204"
"","95,3400","1,5887","1,8498","0,5213"
"","95,4800","1,5910","1,8520","0,5221"
"","95,6200","1,5933","1,8534","0,5230"
"","95,7600","1,5957","1,8562","0,5239"
"","95,9000","1,5980","1,8567","0,5248"
"","96,0400","1,6003","1,8584","0,5256"
"","96,1800","1,6027","1,8608","0,5266"
"","96,3200","1,6050","1,8625","0,5275"
"","96,4600","1,6073","1,8647","0,5284"
"","96,6000","1,6097","1,8655","0,5293"
"","96,7400","1,6120","1,8687","0,5302"
"","96,8800","1,6143","1,8687","0,5310"
"","97,0200","1,6167","1,8717","0,5320"
"","97,1600","1,6190","1,8729","0,5328"
"","97,3000","1,6213","1,8747","0,5337"
"","97,4400","1,6237","1,8763","0,5346"
"","97,5800","1,6260","1,8781","0,5356"
"","97,7200","1,6283","1,8802","0,5364"
"","97,8600","1,6307","1,8814","0,5374"
"","98,0000","1,6330","1,8827","0,5383"
"","98,1400","1,6353","1,8847","0,5392"
"","98,2800","1,6377","1,8865","0,5401"
"","98,4200","1,6400","1,8877","0,5410"
"","98,5600","1,6424","1,8908","0,5419"
"","98,7000","1,6447","1,8924","0,5428"
"","98,8400","1,6469","1,8928","0,5437"
"","98,9800","1,6494","1,8957","0,5447"
"","99,1200","1,6517","1,8966","0,5456"
"","99,2600","1,6540","1,8985","0,5464"
"","99,4000","1,6564","1,9009","0,5474"
"","99,5400","1,6587","1,9026","0,5483"
"","99,6800","1,6610","1,9037","0,5492"
"","99,8200","1,6634","1,9053","0,5501"
"","99,9600","1,6657","1,9078","0,5511"
"","100,1000","1,6680","1,9081","0,5520"
"","100,2400","1,6703","1,9105","0,5529"
"","100,3800","1,6726","1,9132","0,5538"
"","100,5200","1,6750","1,9135","0,5547"
"","100,6600","1,6774","1,9145","0,5556"
"","100,8000","1,6796","1,9179","0,5565"
"","100,9400","1,6820","1,9184","0,5575"
"","101,0800","1,6843","1,9201","0,5583"
"","101,2200","1,6867","1,9224","0,5592"
"","101,3600","1,6890","1,9234","0,5602"
"","101,5000","1,6913","1,9261","0,5611"
"","101,6400","1,6936","1,9270","0,5620"
"","101,7800","1,6960","1,9283","0,5630"
"","101,9200","1,6983","1,9294","0,5639"
"","102,0600","1,7006","1,9305","0,5647"
"","102,2000","1,7030","1,9326","0,5657"
"","102,3400","1,7054","1,9357","0,5666"
"","102,4800","1,7076","1,9365","0,5675"
"","102,6200","1,7100","1,9384","0,5685"
"","102,7600","1,7123","1,9401","0,5694"
"","102,9000","1,7147","1,9412","0,5703"
"","103,0400","1,7170","1,9431","0,5712"
"","103,1800","1,7193","1,9456","0,5721"
"","103,3200","1,7217","1,9456","0,5731"
"","103,4600","1,7240","1,9481","0,5740"
"","103,6000","1,7263","1,9497","0,5750"
"","103,7400","1,7287","1,9513","0,5760"
"","103,8800","1,7310","1,9520","0,5769"
"","104,0200","1,7333","1,9544","0,5777"
"","104,1600","1,7357","1,9565","0,5787"
"","104,3000","1,7380","1,9572","0,5797"
"","104,4400","1,7403","1,9594","0,5805"
"","104,5800","1,7427","1,9605","0,5815"
"","104,7200","1,7450","1,9619","0,5824"
"","104,8600","1,7473","1,9645","0,5833"
"","105,0000","1,7497","1,9660","0,5843"
"","105,1400","1,7520","1,9677","0,5852"
"","105,2800","1,7543","1,9685","0,5861"
"","105,4200","1,7567","1,9706","0,5871"
"","105,5600","1,7590","1,9723","0,5881"
"","105,7000","1,7613","1,9735","0,5890"
"","105,8400","1,7637","1,9752","0,5899"
"","105,9800","1,7660","1,9766","0,5908"
"","106,1200","1,7683","1,9787","0,5918"
"","106,2600","1,7707","1,9805","0,5927"
"","106,4000","1,7729","1,9797","0,5936"
"","106,5400","1,7754","1,9829","0,5947"
"","106,6800","1,7777","1,9831","0,5956"
"","106,8200","1,7799","1,9858","0,5965"
"","106,9600","1,7824","1,9877","0,5975"
"","107,1000","1,7847","1,9893","0,5984"
"","107,2400","1,7869","1,9914","0,5994"
"","107,3800","1,7893","1,9925","0,6004"
"","107,5200","1,7916","1,9936","0,6012"
"","107,6600","1,7939","1,9953","0,6022"
"","107,8000","1,7964","1,9974","0,6032"
"","107,9400","1,7987","1,9993","0,6041"
"","108,0800","1,8010","2,0000","0,6051"
"","108,2200","1,8034","2,0003","0,6060"
"","108,3600","1,8056","2,0030","0,6070"
"","108,5000","1,8080","2,0033","0,6079"
"","108,6400","1,8103","2,0055","0,6089"
"","108,7800","1,8126","2,0078","0,6099"
"","108,9200","1,8150","2,0091","0,6108"
"","109,0600","1,8173","2,0103","0,6118"
"","109,2000","1,8196","2,0120","0,6127"
"","109,3400","1,8221","2,0132","0,6138"
"","109,4800","1,8243","2,0147","0,6147"
"","109,6200","1,8266","2,0165","0,6156"
"","109,7600","1,8290","2,0190","0,6166"
"","109,9000","1,8314","2,0196","0,6175"
"","110,0400","1,8336","2,0210","0,6185"
"","110,1800","1,8360","2,0223","0,6195"
"","110,3200","1,8383","2,0238","0,6205"
"","110,4600","1,8406","2,0255","0,6214"
"","110,6000","1,8430","2,0264","0,6224"
"","110,7400","1,8453","2,0283","0,6233"
"","110,8800","1,8477","2,0299","0,6244"
"","111,0200","1,8500","2,0307","0,6253"
"","111,1600","1,8523","2,0327","0,6263"
"","111,3000","1,8547","2,0342","0,6272"
"","111,4400","1,8570","2,0354","0,6282"
"","111,5800","1,8593","2,0372","0,6291"
"","111,7200","1,8617","2,0389","0,6302"
"","111,8600","1,8640","2,0412","0,6311"
"","112,0000","1,8663","2,0412","0,6320"
"","112,1400","1,8687","2,0424","0,6330"
"","112,2800","1,8710","2,0444","0,6340"
"","112,4200","1,8733","2,0465","0,6349"
"","112,5600","1,8757","2,0475","0,6360"
"","112,7000","1,8780","2,0499","0,6369"
"","112,8400","1,8803","2,0493","0,6379"
"","112,9800","1,8827","2,0521","0,6389"
"","113,1200","1,8850","2,0531","0,6399"
"","113,2600","1,8873","2,0544","0,6408"
"","113,4000","1,8897","2,0562","0,6418"
"","113,5400","1,8920","2,0579","0,6428"
"","113,6800","1,8943","2,0589","0,6438"
"","113,8200","1,8967","2,0597","0,6448"
"","113,9600","1,8990","2,0613","0,6457"
"","114,1000","1,9014","2,0636","0,6468"
"","114,2400","1,9036","2,0635","0,6477"
"","114,3800","1,9059","2,0655","0,6487"
"","114,5200","1,9084","2,0673","0,6497"
"","114,6600","1,9107","2,0686","0,6507"
"","114,8000","1,9130","2,0703","0,6516"
"","114,9400","1,9154","2,0713","0,6526"
"","115,0800","1,9177","2,0729","0,6536"
"","115,2200","1,9199","2,0740","0,6546"
"","115,3600","1,9224","2,0754","0,6557"
"","115,5000","1,9247","2,0758","0,6566"
"","115,6400","1,9269","2,0789","0,6575"
"","115,7800","1,9294","2,0806","0,6586"
"","115,9200","1,9317","2,0803","0,6596"
"","116,0600","1,9340","2,0824","0,6606"
"","116,2000","1,9364","2,0845","0,6616"
"","116,3400","1,9386","2,0852","0,6626"
"","116,4800","1,9410","2,0864","0,6636"
"","116,6200","1,9434","2,0881","0,6646"
"","116,7600","1,9457","2,0892","0,6656"
"","116,9000","1,9480","2,0909","0,6666"
"","117,0400","1,9504","2,0919","0,6676"
"","117,1800","1,9526","2,0929","0,6685"
"","117,3200","1,9551","2,0944","0,6696"
"","117,4600","1,9573","2,0952","0,6706"
"","117,6000","1,9596","2,0973","0,6715"
"","117,7400","1,9620","2,0986","0,6725"
"","117,8800","1,9643","2,1002","0,6735"
"","118,0200","1,9666","2,1015","0,6745"
"","118,1600","1,9690","2,1026","0,6756"
"","118,3000","1,9713","2,1039","0,6766"
"","118,4400","1,9737","2,1056","0,6776"
"","118,5800","1,9760","2,1071","0,6787"
"","118,7200","1,9783","2,1077","0,6797"
"","118,8600","1,9807","2,1097","0,6807"
"","119,0000","1,9830","2,1107","0,6816"
"","119,1400","1,9852","2,1115","0,6826"
"","119,2800","1,9877","2,1137","0,6836"
"","119,4200","1,9900","2,1144","0,6847"
"","119,5600","1,9923","2,1150","0,6856"
"","119,7000","1,9947","2,1170","0,6867"
"","119,8400","1,9970","2,1187","0,6877"
"","119,9800","1,9993","2,1198","0,6887"
"","120,1200","2,0018","2,1199","0,6898"
"","120,2600","2,0040","2,1225","0,6908"
"","120,4000","2,0063","2,1223","0,6917"
"","120,5400","2,0087","2,1242","0,6927"
"","120,6800","2,0110","2,1262","0,6937"
"","120,8200","2,0132","2,1275","0,6947"
"","120,9600","2,0157","2,1289","0,6958"
"","121,1000","2,0180","2,1298","0,6968"
"","121,2400","2,0203","2,1305","0,6978"
"","121,3800","2,0227","2,1326","0,6988"
"","121,5200","2,0250","2,1335","0,6998"
"","121,6600","2,0274","2,1357","0,7010"
"","121,8000","2,0297","2,1357","0,7019"
"","121,9400","2,0319","2,1372","0,7028"
"","122,0800","2,0344","2,1382","0,7039"
"","122,2200","2,0367","2,1410","0,7050"
"","122,3600","2,0389","2,1408","0,7059"
"","122,5000","2,0414","2,1426","0,7071"
"","122,6400","2,0437","2,1445","0,7080"
"","122,7800","2,0460","2,1437","0,7090"
"","122,9200","2,0484","2,1455","0,7101"
"","123,0600","2,0507","2,1474","0,7111"
"","123,2000","2,0530","2,1485","0,7121"
"","123,3400","2,0554","2,1493","0,7131"
"","123,4800","2,0577","2,1502","0,7141"
"","123,6200","2,0599","2,1521","0,7151"
"","123,7600","2,0624","2,1536","0,7162"
"","123,9000","2,0647","2,1548","0,7172"
"","124,0400","2,0670","2,1546","0,7183"
"","124,1800","2,0694","2,1566","0,7193"
"","124,3200","2,0717","2,1582","0,7205"
"","124,4600","2,0740","2,1586","0,7213"
"","124,6000","2,0764","2,1604","0,7224"
"","124,7400","2,0787","2,1611","0,7234"
"","124,8800","2,0811","2,1632","0,7245"
"","125,0200","2,0833","2,1635","0,7255"
"","125,1600","2,0856","2,1647","0,7265"
"","125,3000","2,0880","2,1665","0,7276"
"","125,4400","2,0904","2,1671","0,7286"
"","125,5800","2,0926","2,1673","0,7297"
"","125,7200","2,0950","2,1689","0,7307"
"","125,8600","2,0973","2,1714","0,7318"
"","126,0000","2,0996","2,1722","0,7328"
"","126,1400","2,1020","2,1736","0,7339"
"","126,2800","2,1043","2,1741","0,7349"
"","126,4200","2,1066","2,1749","0,7359"
"","126,5600","2,1090","2,1763","0,7370"
"","126,7000","2,1113","2,1775","0,7380"
"","126,8400","2,1137","2,1796","0,7390"
"","126,9800","2,1160","2,1806","0,7401"
"","127,1200","2,1183","2,1810","0,7411"
"","127,2600","2,1207","2,1833","0,7422"
"","127,4000","2,1230","2,1833","0,7433"
"","127,5400","2,1253","2,1837","0,7443"
"","127,6800","2,1277","2,1859","0,7454"
"","127,8200","2,1300","2,1871","0,7464"
"","127,9600","2,1323","2,1887","0,7474"
"","128,1000","2,1347","2,1895","0,7485"
"","128,2400","2,1370","2,1909","0,7495"
"","128,3800","2,1393","2,1918","0,7505"
"","128,5200","2,1417","2,1937","0,7516"
"","128,6600","2,1440","2,1935","0,7526"
"","128,8000","2,1463","2,1943","0,7537"
"","128,9400","2,1487","2,1959","0,7548"
"","129,0800","2,1509","2,1963","0,7558"
"","129,2200","2,1533","2,1980","0,7569"
"","129,3600","2,1557","2,1990","0,7580"
"","129,5000","2,1580","2,2002","0,7590"
"","129,6400","2,1604","2,2021","0,7601"
"","129,7800","2,1627","2,2020","0,7611"
"","129,9200","2,1649","2,2040","0,7621"
"","130,0600","2,1674","2,2044","0,7632"
"","130,2000","2,1697","2,2055","0,7642"
"","130,3400","2,1719","2,2072","0,7653"
"","130,4800","2,1744","2,2081","0,7664"
"","130,6200","2,1767","2,2090","0,7674"
"","130,7600","2,1790","2,2104","0,7684"
"","130,9000","2,1814","2,2114","0,7696"
"","131,0400","2,1837","2,2126","0,7706"
"","131,1800","2,1859","2,2125","0,7717"
"","131,3200","2,1883","2,2137","0,7728"
"","131,4600","2,1907","2,2151","0,7738"
"","131,6000","2,1929","2,2165","0,7749"
"","131,7400","2,1953","2,2177","0,7759"
"","131,8800","2,1976","2,2191","0,7771"
"","132,0200","2,2000","2,2196","0,7781"
"","132,1600","2,2023","2,2205","0,7792"
"","132,3000","2,2047","2,2219","0,7802"
"","132,4400","2,2071","2,2232","0,7814"
"","132,5800","2,2093","2,2235","0,7824"
"","132,7200","2,2116","2,2253","0,7834"
"","132,8600","2,2140","2,2260","0,7846"
"","133,0000","2,2163","2,2271","0,7856"
"","133,1400","2,2186","2,2273","0,7867"
"","133,2800","2,2210","2,2291","0,7878"
"","133,4200","2,2234","2,2310","0,7889"
"","133,5600","2,2257","2,2298","0,7899"
"","133,7000","2,2280","2,2318","0,7911"
"","133,8400","2,2304","2,2327","0,7921"
"","133,9800","2,2326","2,2344","0,7932"
"","134,1200","2,2350","2,2354","0,7943"
"","134,2600","2,2373","2,2355","0,7953"
"","134,4000","2,2396","2,2357","0,7964"
"","134,5400","2,2420","2,2387","0,7975"
"","134,6800","2,2443","2,2397","0,7985"
"","134,8200","2,2466","2,2396","0,7997"
"","134,9600","2,2490","2,2410","0,8008"
"","135,1000","2,2513","2,2412","0,8018"
"","135,2400","2,2537","2,2430","0,8030"
"","135,3800","2,2560","2,2428","0,8040"
"","135,5200","2,2583","2,2446","0,8051"
"","135,6600","2,2607","2,2471","0,8062"
"","135,8000","2,2630","2,2468","0,8073"
"","135,9400","2,2652","2,2477","0,8083"
"","136,0800","2,2677","2,2481","0,8095"
"","136,2200","2,2700","2,2496","0,8105"
"","136,3600","2,2723","2,2512","0,8116"
"","136,5000","2,2747","2,2522","0,8128"
"","136,6400","2,2770","2,2516","0,8138"
"","136,7800","2,2793","2,2543","0,8149"
"","136,9200","2,2817","2,2554","0,8160"
"","137,0600","2,2840","2,2557","0,8171"
"","137,2000","2,2863","2,2565","0,8182"
"","137,3400","2,2887","2,2578","0,8193"
"","137,4800","2,2910","2,2591","0,8204"
"","137,6200","2,2933","2,2598","0,8215"
"","137,7600","2,2957","2,2609","0,8227"
"","137,9000","2,2980","2,2606","0,8236"
"","138,0400","2,3003","2,2631","0,8248"
"","138,1800","2,3027","2,2639","0,8259"
"","138,3200","2,3050","2,2649","0,8270"
"","138,4600","2,3074","2,2660","0,8282"
"","138,6000","2,3097","2,2662","0,8292"
"","138,7400","2,3119","2,2676","0,8303"
"","138,8800","2,3144","2,2687","0,8315"
"","139,0200","2,3167","2,2692","0,8325"
"","139,1600","2,3190","2,2702","0,8336"
"","139,3000","2,3214","2,2714","0,8347"
"","139,4400","2,3237","2,2707","0,8358"
"","139,5800","2,3260","2,2720","0,8369"
"","139,7200","2,3283","2,2735","0,8381"
"","139,8600","2,3306","2,2737","0,8391"
"","140,0000","2,3330","2,2749","0,8403"
"","140,1400","2,3353","2,2762","0,8414"
"","140,2800","2,3376","2,2779","0,8425"
"","140,4200","2,3401","2,2787","0,8437"
"","140,5600","2,3423","2,2803","0,8447"
"","140,7000","2,3446","2,2801","0,8458"
"","140,8400","2,3470","2,2800","0,8470"
"","140,9800","2,3494","2,2813","0,8481"
"","141,1200","2,3516","2,2821","0,8492"
"","141,2600","2,3540","2,2839","0,8503"
"","141,4000","2,3564","2,2841","0,8515"
"","141,5400","2,3586","2,2860","0,8526"
"","141,6800","2,3610","2,2862","0,8537"
"","141,8200","2,3633","2,2862","0,8549"
"","141,9600","2,3656","2,2888","0,8560"
"","142,1000","2,3680","2,2895","0,8571"
"","142,2400","2,3704","2,2896","0,8583"
"","142,3800","2,3727","2,2912","0,8593"
"","142,5200","2,3750","2,2918","0,8605"
"","142,6600","2,3773","2,2917","0,8616"
"","142,8000","2,3797","2,2935","0,8627"
"","142,9400","2,3820","2,2943","0,8639"
"","143,0800","2,3843","2,2950","0,8650"
"","143,2200","2,3867","2,2963","0,8662"
"","143,3600","2,3890","2,2966","0,8672"
"","143,5000","2,3913","2,2964","0,8684"
"","143,6400","2,3937","2,2990","0,8696"
"","143,7800","2,3960","2,2997","0,8707"
"","143,9200","2,3983","2,3002","0,8718"
"","144,0600","2,4007","2,3015","0,8731"
"","144,2000","2,4030","2,3020","0,8742"
"","144,3400","2,4053","2,3028","0,8752"
"","144,4800","2,4077","2,3046","0,8764"
"","144,6200","2,4100","2,3034","0,8776"
"","144,7600","2,4123","2,3056","0,8787"
"","144,9000","2,4147","2,3060","0,8798"
"","145,0400","2,4170","2,3070","0,8809"
"","145,1800","2,4193","2,3064","0,8820"
"","145,3200","2,4217","2,3084","0,8832"
"","145,4600","2,4240","2,3091","0,8843"
"","145,6000","2,4264","2,3099","0,8855"
"","145,7400","2,4287","2,3117","0,8867"
"","145,8800","2,4310","2,3122","0,8877"
"","146,0200","2,4334","2,3130","0,8889"
"","146,1600","2,4357","2,3142","0,8901"
"","146,3000","2,4380","2,3135","0,8912"
"","146,4400","2,4404","2,3150","0,8924"
"","146,5800","2,4426","2,3158","0,8935"
"","146,7200","2,4449","2,3166","0,8946"
"","146,8600","2,4474","2,3179","0,8959"
"","147,0000","2,4497","2,3189","0,8970"
"","147,1400","2,4520","2,3196","0,8981"
"","147,2800","2,4544","2,3200","0,8993"
"","147,4200","2,4567","2,3199","0,9004"
"","147,5600","2,4590","2,3207","0,9016"
"","147,7000","2,4613","2,3227","0,9028"
"","147,8400","2,4636","2,3229","0,9039"
"","147,9800","2,4660","2,3232","0,9050"
"","148,1200","2,4683","2,3243","0,9062"
"","148,2600","2,4706","2,3253","0,9073"
"","148,4000","2,4730","2,3265","0,9085"
"","148,5400","2,4754","2,3270","0,9097"
"","148,6800","2,4776","2,3273","0,9108"
"","148,8200","2,4800","2,3282","0,9120"
"","148,9600","2,4824","2,3295","0,9132"
"","149,1000","2,4846","2,3295","0,9143"
"","149,2400","2,4870","2,3301","0,9155"
"","149,3800","2,4893","2,3321","0,9166"
"","149,5200","2,4916","2,3315","0,9177"
"","149,6600","2,4941","2,3329","0,9190"
"","149,8000","2,4963","2,3335","0,9201"
"","149,9400","2,4986","2,3349","0,9212"
"","150,0800","2,5010","2,3353","0,9224"
"","150,2200","2,5033","2,3372","0,9236"
"","150,3600","2,5057","2,3356","0,9248"
"","150,5000","2,5080","2,3373","0,9260"
"","150,6400","2,5103","2,3389","0,9271"
"","150,7800","2,5127","2,3388","0,9283"
"","150,9200","2,5150","2,3393","0,9295"
"","151,0600","2,5173","2,3408","0,9306"
"","151,2000","2,5197","2,3412","0,9318"
"","151,3400","2,5220","2,3414","0,9330"
"","151,4800","2,5243","2,3430","0,9341"
"","151,6200","2,5267","2,3433","0,9354"
"","151,7600","2,5290","2,3442","0,9366"
"","151,9000","2,5313","2,3455","0,9377"
"","152,0400","2,5337","2,3454","0,9390"
"","152,1800","2,5360","2,3460","0,9401"
"","152,3200","2,5383","2,3470","0,9412"
"","152,4600","2,5407","2,3482","0,9425"
"","152,6000","2,5430","2,3486","0,9436"
"","152,7400","2,5453","2,3494","0,9448"
"","152,8800","2,5477","2,3490","0,9459"
"","153,0200","2,5500","2,3508","0,9471"
"","153,1600","2,5524","2,3510","0,9484"
"","153,3000","2,5547","2,3511","0,9495"
"","153,4400","2,5570","2,3521","0,9507"
"","153,5800","2,5594","2,3528","0,9519"
"","153,7200","2,5616","2,3543","0,9531"
"","153,8600","2,5639","2,3544","0,9542"
"","154,0000","2,5664","2,3545","0,9555"
"","154,1400","2,5687","2,3553","0,9567"
"","154,2800","2,5710","2,3563","0,9579"
"","154,4200","2,5734","2,3563","0,9591"
"","154,5600","2,5757","2,3572","0,9603"
"","154,7000","2,5780","2,3588","0,9615"
"","154,8400","2,5804","2,3598","0,9628"
"","154,9800","2,5827","2,3598","0,9639"
"","155,1200","2,5850","2,3600","0,9651"
"","155,2600","2,5873","2,3611","0,9663"
"","155,4000","2,5896","2,3616","0,9674"
"","155,5400","2,5920","2,3626","0,9688"
"","155,6800","2,5944","2,3628","0,9699"
"","155,8200","2,5966","2,3636","0,9711"
"","155,9600","2,5990","2,3647","0,9723"
"","156,1000","2,6014","2,3657","0,9736"
"","156,2400","2,6036","2,3654","0,9748"
"","156,3800","2,6060","2,3661","0,9759"
"","156,5200","2,6084","2,3667","0,9771"
"","156,6600","2,6106","2,3674","0,9783"
"","156,8000","2,6130","2,3685","0,9797"
"","156,9400","2,6154","2,3690","0,9808"
"","157,0800","2,6177","2,3684","0,9820"
"","157,2200","2,6200","2,3692","0,9832"
"","157,3600","2,6223","2,3705","0,9844"
"","157,5000","2,6246","2,3704","0,9857"
"","157,6400","2,6270","2,3713","0,9870"
"","157,7800","2,6293","2,3721","0,9881"
"","157,9200","2,6317","2,3722","0,9894"
"","158,0600","2,6340","2,3725","0,9906"
"","158,2000","2,6363","2,3734","0,9919"
"","158,3400","2,6387","2,3736","0,9932"
"","158,4800","2,6410","2,3748","0,9945"
"","158,6200","2,6433","2,3746","0,9957"
"","158,7600","2,6457","2,3749","0,9971"
"","158,9000","2,6480","2,3756","0,9984"
"","159,0400","2,6503","2,3755","0,9996"
"","159,1800","2,6527","2,3758","1,0012"
"","159,3180","2,6550","1,6940","0,7564"
"","159,4410","2,6572","0,0046","-0,2503"
"","159,5810","2,6594","0,0004","-0,2625"
"","159,7210","2,6617","0,0009","-0,2686"
"","159,8610","2,6640","0,0001","-0,2730"
"","160,0010","2,6664","0,0009","-0,2764"
"","160,1410","2,6687","0,0015","-0,2791"
"","160,2810","2,6710","0,0004","-0,2814"
"","160,4210","2,6734","0,0004","-0,2833"
"","160,5610","2,6757","-0,0003","-0,2849"
"","160,7010","2,6780","0,0005","-0,2864"
"","160,8410","2,6804","0,0005","-0,2877"
"","160,9810","2,6827","0,0009","-0,2890"
"","161,1210","2,6850","0,0004","-0,2902"
"","161,2610","2,6873","0,0010","-0,2913"
"","161,4010","2,6896","0,0010","-0,2924"
"","161,5410","2,6921","0,0005","-0,2932"
"","161,6810","2,6944","0,0004","-0,2941"
"","161,8210","2,6966","0,0009","-0,2949"
"","161,9610","2,6991","0,0012","-0,2956"
"","162,1010","2,7013","0,0003","-0,2963"
"","162,2410","2,7036","0,0008","-0,2970"
"","162,3810","2,7061","0,0014","-0,2976"
"","162,5210","2,7084","0,0004","-0,2982"
"","162,6610","2,7106","0,0005","-0,2988"
"","162,8010","2,7131","0,0004","-0,2994"
"","162,9410","2,7154","0,0007","-0,2999"
"","163,0810","2,7177","0,0017","-0,3004"
"","163,2210","2,7200","0,0004","-0,3009"
"","163,3610","2,7223","0,0008","-0,3014"
"","163,5010","2,7247","0,0004","-0,3018"
"","163,6410","2,7270","0,0009","-0,3023"
"","163,7810","2,7293","-0,0001","-0,3027"
"","163,9210","2,7317","0,0008","-0,3031"
"","164,0610","2,7340","-0,0006","-0,3035"
"","164,2010","2,7363","0,0010","-0,3039"
"","164,3410","2,7387","0,0005","-0,3043"
"","164,4810","2,7410","0,0011","-0,3046"
"","164,5290","2,7418","0,0004","-0,3048"